[2023-06-29T10:56:48.165+0530] {taskinstance.py:1103} INFO - Dependencies all met for dep_context=non-requeueable deps ti=<TaskInstance: Dag_v3.first_task scheduled__2023-06-28T00:00:00+00:00 [queued]>
[2023-06-29T10:56:48.172+0530] {taskinstance.py:1103} INFO - Dependencies all met for dep_context=requeueable deps ti=<TaskInstance: Dag_v3.first_task scheduled__2023-06-28T00:00:00+00:00 [queued]>
[2023-06-29T10:56:48.172+0530] {taskinstance.py:1308} INFO - Starting attempt 5 of 6
[2023-06-29T10:56:48.198+0530] {taskinstance.py:1327} INFO - Executing <Task(BashOperator): first_task> on 2023-06-28 00:00:00+00:00
[2023-06-29T10:56:48.200+0530] {standard_task_runner.py:57} INFO - Started process 13239 to run task
[2023-06-29T10:56:48.203+0530] {standard_task_runner.py:84} INFO - Running: ['airflow', 'tasks', 'run', 'Dag_v3', 'first_task', 'scheduled__2023-06-28T00:00:00+00:00', '--job-id', '47', '--raw', '--subdir', 'DAGS_FOLDER/dag_with_bash_operator.py', '--cfg-path', '/tmp/tmp9i1awu65']
[2023-06-29T10:56:48.204+0530] {standard_task_runner.py:85} INFO - Job 47: Subtask first_task
[2023-06-29T10:56:48.252+0530] {task_command.py:410} INFO - Running <TaskInstance: Dag_v3.first_task scheduled__2023-06-28T00:00:00+00:00 [running]> on host neosoft-Latitude-E5270
[2023-06-29T10:56:48.310+0530] {taskinstance.py:1545} INFO - Exporting env vars: AIRFLOW_CTX_DAG_OWNER='airflow' AIRFLOW_CTX_DAG_ID='Dag_v3' AIRFLOW_CTX_TASK_ID='first_task' AIRFLOW_CTX_EXECUTION_DATE='2023-06-28T00:00:00+00:00' AIRFLOW_CTX_TRY_NUMBER='5' AIRFLOW_CTX_DAG_RUN_ID='scheduled__2023-06-28T00:00:00+00:00'
[2023-06-29T10:56:48.311+0530] {subprocess.py:63} INFO - Tmp dir root location: /tmp
[2023-06-29T10:56:48.312+0530] {subprocess.py:75} INFO - Running command: ['/usr/bin/bash', '-c', 'this is the first task']
[2023-06-29T10:56:48.317+0530] {subprocess.py:86} INFO - Output:
[2023-06-29T10:56:48.318+0530] {subprocess.py:93} INFO - /usr/bin/bash: this: command not found
[2023-06-29T10:56:48.319+0530] {subprocess.py:97} INFO - Command exited with return code 127
[2023-06-29T10:56:48.327+0530] {taskinstance.py:1824} ERROR - Task failed with exception
Traceback (most recent call last):
  File "/home/neosoft/airflow/py_env/lib/python3.8/site-packages/airflow/operators/bash.py", line 210, in execute
    raise AirflowException(
airflow.exceptions.AirflowException: Bash command failed. The command returned a non-zero exit code 127.
[2023-06-29T10:56:48.330+0530] {taskinstance.py:1345} INFO - Marking task as UP_FOR_RETRY. dag_id=Dag_v3, task_id=first_task, execution_date=20230628T000000, start_date=20230629T052648, end_date=20230629T052648
[2023-06-29T10:56:48.356+0530] {standard_task_runner.py:104} ERROR - Failed to execute job 47 for task first_task (Bash command failed. The command returned a non-zero exit code 127.; 13239)
[2023-06-29T10:56:48.375+0530] {local_task_job_runner.py:225} INFO - Task exited with return code 1
[2023-06-29T10:56:48.402+0530] {taskinstance.py:2653} INFO - 0 downstream tasks scheduled from follow-on schedule check
