[2023-06-28T19:33:10.603+0530] {taskinstance.py:1103} INFO - Dependencies all met for dep_context=non-requeueable deps ti=<TaskInstance: Dag_v3.first_task scheduled__2023-06-28T00:00:00+00:00 [queued]>
[2023-06-28T19:33:10.611+0530] {taskinstance.py:1103} INFO - Dependencies all met for dep_context=requeueable deps ti=<TaskInstance: Dag_v3.first_task scheduled__2023-06-28T00:00:00+00:00 [queued]>
[2023-06-28T19:33:10.612+0530] {taskinstance.py:1308} INFO - Starting attempt 4 of 6
[2023-06-28T19:33:10.642+0530] {taskinstance.py:1327} INFO - Executing <Task(BashOperator): first_task> on 2023-06-28 00:00:00+00:00
[2023-06-28T19:33:10.646+0530] {standard_task_runner.py:57} INFO - Started process 347411 to run task
[2023-06-28T19:33:10.652+0530] {standard_task_runner.py:84} INFO - Running: ['airflow', 'tasks', 'run', 'Dag_v3', 'first_task', 'scheduled__2023-06-28T00:00:00+00:00', '--job-id', '45', '--raw', '--subdir', 'DAGS_FOLDER/dag_with_bash_operator.py', '--cfg-path', '/tmp/tmpu_3lmoao']
[2023-06-28T19:33:10.653+0530] {standard_task_runner.py:85} INFO - Job 45: Subtask first_task
[2023-06-28T19:33:10.725+0530] {task_command.py:410} INFO - Running <TaskInstance: Dag_v3.first_task scheduled__2023-06-28T00:00:00+00:00 [running]> on host neosoft-Latitude-E5270
[2023-06-28T19:33:10.787+0530] {taskinstance.py:1545} INFO - Exporting env vars: AIRFLOW_CTX_DAG_OWNER='airflow' AIRFLOW_CTX_DAG_ID='Dag_v3' AIRFLOW_CTX_TASK_ID='first_task' AIRFLOW_CTX_EXECUTION_DATE='2023-06-28T00:00:00+00:00' AIRFLOW_CTX_TRY_NUMBER='4' AIRFLOW_CTX_DAG_RUN_ID='scheduled__2023-06-28T00:00:00+00:00'
[2023-06-28T19:33:10.789+0530] {subprocess.py:63} INFO - Tmp dir root location: /tmp
[2023-06-28T19:33:10.789+0530] {subprocess.py:75} INFO - Running command: ['/usr/bin/bash', '-c', 'this is the first task']
[2023-06-28T19:33:10.795+0530] {subprocess.py:86} INFO - Output:
[2023-06-28T19:33:10.796+0530] {subprocess.py:93} INFO - /usr/bin/bash: this: command not found
[2023-06-28T19:33:10.796+0530] {subprocess.py:97} INFO - Command exited with return code 127
[2023-06-28T19:33:10.805+0530] {taskinstance.py:1824} ERROR - Task failed with exception
Traceback (most recent call last):
  File "/home/neosoft/airflow/py_env/lib/python3.8/site-packages/airflow/operators/bash.py", line 210, in execute
    raise AirflowException(
airflow.exceptions.AirflowException: Bash command failed. The command returned a non-zero exit code 127.
[2023-06-28T19:33:10.808+0530] {taskinstance.py:1345} INFO - Marking task as UP_FOR_RETRY. dag_id=Dag_v3, task_id=first_task, execution_date=20230628T000000, start_date=20230628T140310, end_date=20230628T140310
[2023-06-28T19:33:10.848+0530] {standard_task_runner.py:104} ERROR - Failed to execute job 45 for task first_task (Bash command failed. The command returned a non-zero exit code 127.; 347411)
[2023-06-28T19:33:10.863+0530] {local_task_job_runner.py:225} INFO - Task exited with return code 1
[2023-06-28T19:33:10.896+0530] {taskinstance.py:2653} INFO - 0 downstream tasks scheduled from follow-on schedule check
