[2023-07-20T12:53:32.216+0530] {taskinstance.py:1103} INFO - Dependencies all met for dep_context=non-requeueable deps ti=<TaskInstance: spark_data_processing.send_email scheduled__2023-07-02T08:00:00+00:00 [queued]>
[2023-07-20T12:53:32.223+0530] {taskinstance.py:1103} INFO - Dependencies all met for dep_context=requeueable deps ti=<TaskInstance: spark_data_processing.send_email scheduled__2023-07-02T08:00:00+00:00 [queued]>
[2023-07-20T12:53:32.223+0530] {taskinstance.py:1308} INFO - Starting attempt 4 of 6
[2023-07-20T12:53:32.259+0530] {taskinstance.py:1327} INFO - Executing <Task(EmailOperator): send_email> on 2023-07-02 08:00:00+00:00
[2023-07-20T12:53:32.261+0530] {standard_task_runner.py:57} INFO - Started process 83071 to run task
[2023-07-20T12:53:32.264+0530] {standard_task_runner.py:84} INFO - Running: ['airflow', 'tasks', 'run', 'spark_data_processing', 'send_email', 'scheduled__2023-07-02T08:00:00+00:00', '--job-id', '419', '--raw', '--subdir', 'DAGS_FOLDER/assignment2.py', '--cfg-path', '/tmp/tmpqgjl7p6x']
[2023-07-20T12:53:32.265+0530] {standard_task_runner.py:85} INFO - Job 419: Subtask send_email
[2023-07-20T12:53:32.316+0530] {task_command.py:410} INFO - Running <TaskInstance: spark_data_processing.send_email scheduled__2023-07-02T08:00:00+00:00 [running]> on host neosoft-Latitude-E5270
[2023-07-20T12:53:32.379+0530] {taskinstance.py:1545} INFO - Exporting env vars: AIRFLOW_CTX_DAG_EMAIL='nikitaneti21@gmail.com' AIRFLOW_CTX_DAG_OWNER='Nikita' AIRFLOW_CTX_DAG_ID='spark_data_processing' AIRFLOW_CTX_TASK_ID='send_email' AIRFLOW_CTX_EXECUTION_DATE='2023-07-02T08:00:00+00:00' AIRFLOW_CTX_TRY_NUMBER='4' AIRFLOW_CTX_DAG_RUN_ID='scheduled__2023-07-02T08:00:00+00:00'
[2023-07-20T12:53:32.385+0530] {base.py:73} INFO - Using connection ID 'smtp_default' for task execution.
[2023-07-20T12:53:32.386+0530] {email.py:268} INFO - Email alerting: attempt 1
[2023-07-20T12:53:34.224+0530] {taskinstance.py:1824} ERROR - Task failed with exception
Traceback (most recent call last):
  File "/home/neosoft/airflow/py_env/lib/python3.8/site-packages/airflow/operators/email.py", line 77, in execute
    send_email(
  File "/home/neosoft/airflow/py_env/lib/python3.8/site-packages/airflow/utils/email.py", line 78, in send_email
    return backend(
  File "/home/neosoft/airflow/py_env/lib/python3.8/site-packages/airflow/utils/email.py", line 152, in send_email_smtp
    send_mime_email(e_from=mail_from, e_to=recipients, mime_msg=msg, conn_id=conn_id, dryrun=dryrun)
  File "/home/neosoft/airflow/py_env/lib/python3.8/site-packages/airflow/utils/email.py", line 279, in send_mime_email
    smtp_conn.login(smtp_user, smtp_password)
  File "/usr/lib/python3.8/smtplib.py", line 743, in login
    raise last_exception
  File "/usr/lib/python3.8/smtplib.py", line 732, in login
    (code, resp) = self.auth(
  File "/usr/lib/python3.8/smtplib.py", line 655, in auth
    raise SMTPAuthenticationError(code, resp)
smtplib.SMTPAuthenticationError: (534, b'5.7.9 Application-specific password required. Learn more at\n5.7.9  https://support.google.com/mail/?p=InvalidSecondFactor 17-20020aa79211000000b0063f1a1e3003sm412547pfo.166 - gsmtp')
[2023-07-20T12:53:34.237+0530] {taskinstance.py:1345} INFO - Marking task as UP_FOR_RETRY. dag_id=spark_data_processing, task_id=send_email, execution_date=20230702T080000, start_date=20230720T072332, end_date=20230720T072334
[2023-07-20T12:53:34.256+0530] {base.py:73} INFO - Using connection ID 'smtp_default' for task execution.
[2023-07-20T12:53:34.257+0530] {email.py:268} INFO - Email alerting: attempt 1
[2023-07-20T12:53:36.110+0530] {base.py:73} INFO - Using connection ID 'smtp_default' for task execution.
[2023-07-20T12:53:36.111+0530] {email.py:268} INFO - Email alerting: attempt 1
[2023-07-20T12:53:37.968+0530] {taskinstance.py:1889} ERROR - Failed to send email to: ['nikitaneti21@gmail.com']
Traceback (most recent call last):
  File "/home/neosoft/airflow/py_env/lib/python3.8/site-packages/airflow/models/taskinstance.py", line 1407, in _run_raw_task
    self._execute_task_with_callbacks(context, test_mode)
  File "/home/neosoft/airflow/py_env/lib/python3.8/site-packages/airflow/models/taskinstance.py", line 1558, in _execute_task_with_callbacks
    result = self._execute_task(context, task_orig)
  File "/home/neosoft/airflow/py_env/lib/python3.8/site-packages/airflow/models/taskinstance.py", line 1628, in _execute_task
    result = execute_callable(context=context)
  File "/home/neosoft/airflow/py_env/lib/python3.8/site-packages/airflow/operators/email.py", line 77, in execute
    send_email(
  File "/home/neosoft/airflow/py_env/lib/python3.8/site-packages/airflow/utils/email.py", line 78, in send_email
    return backend(
  File "/home/neosoft/airflow/py_env/lib/python3.8/site-packages/airflow/utils/email.py", line 152, in send_email_smtp
    send_mime_email(e_from=mail_from, e_to=recipients, mime_msg=msg, conn_id=conn_id, dryrun=dryrun)
  File "/home/neosoft/airflow/py_env/lib/python3.8/site-packages/airflow/utils/email.py", line 279, in send_mime_email
    smtp_conn.login(smtp_user, smtp_password)
  File "/usr/lib/python3.8/smtplib.py", line 743, in login
    raise last_exception
  File "/usr/lib/python3.8/smtplib.py", line 732, in login
    (code, resp) = self.auth(
  File "/usr/lib/python3.8/smtplib.py", line 655, in auth
    raise SMTPAuthenticationError(code, resp)
smtplib.SMTPAuthenticationError: (534, b'5.7.9 Application-specific password required. Learn more at\n5.7.9  https://support.google.com/mail/?p=InvalidSecondFactor 17-20020aa79211000000b0063f1a1e3003sm412547pfo.166 - gsmtp')

During handling of the above exception, another exception occurred:

Traceback (most recent call last):
  File "/home/neosoft/airflow/py_env/lib/python3.8/site-packages/airflow/models/taskinstance.py", line 2295, in email_alert
    send_email(task.email, subject, html_content)
  File "/home/neosoft/airflow/py_env/lib/python3.8/site-packages/airflow/utils/email.py", line 78, in send_email
    return backend(
  File "/home/neosoft/airflow/py_env/lib/python3.8/site-packages/airflow/utils/email.py", line 152, in send_email_smtp
    send_mime_email(e_from=mail_from, e_to=recipients, mime_msg=msg, conn_id=conn_id, dryrun=dryrun)
  File "/home/neosoft/airflow/py_env/lib/python3.8/site-packages/airflow/utils/email.py", line 279, in send_mime_email
    smtp_conn.login(smtp_user, smtp_password)
  File "/usr/lib/python3.8/smtplib.py", line 743, in login
    raise last_exception
  File "/usr/lib/python3.8/smtplib.py", line 732, in login
    (code, resp) = self.auth(
  File "/usr/lib/python3.8/smtplib.py", line 655, in auth
    raise SMTPAuthenticationError(code, resp)
smtplib.SMTPAuthenticationError: (534, b'5.7.9 Application-specific password required. Learn more at\n5.7.9  https://support.google.com/mail/?p=InvalidSecondFactor jb5-20020a170903258500b001b8a37ffb5asm546944plb.4 - gsmtp')

During handling of the above exception, another exception occurred:

Traceback (most recent call last):
  File "/home/neosoft/airflow/py_env/lib/python3.8/site-packages/airflow/models/taskinstance.py", line 1887, in handle_failure
    self.email_alert(error, task)
  File "/home/neosoft/airflow/py_env/lib/python3.8/site-packages/airflow/models/taskinstance.py", line 2297, in email_alert
    send_email(task.email, subject, html_content_err)
  File "/home/neosoft/airflow/py_env/lib/python3.8/site-packages/airflow/utils/email.py", line 78, in send_email
    return backend(
  File "/home/neosoft/airflow/py_env/lib/python3.8/site-packages/airflow/utils/email.py", line 152, in send_email_smtp
    send_mime_email(e_from=mail_from, e_to=recipients, mime_msg=msg, conn_id=conn_id, dryrun=dryrun)
  File "/home/neosoft/airflow/py_env/lib/python3.8/site-packages/airflow/utils/email.py", line 279, in send_mime_email
    smtp_conn.login(smtp_user, smtp_password)
  File "/usr/lib/python3.8/smtplib.py", line 743, in login
    raise last_exception
  File "/usr/lib/python3.8/smtplib.py", line 732, in login
    (code, resp) = self.auth(
  File "/usr/lib/python3.8/smtplib.py", line 655, in auth
    raise SMTPAuthenticationError(code, resp)
smtplib.SMTPAuthenticationError: (534, b'5.7.9 Application-specific password required. Learn more at\n5.7.9  https://support.google.com/mail/?p=InvalidSecondFactor m22-20020a637d56000000b0054a15146f53sm421863pgn.13 - gsmtp')
[2023-07-20T12:53:38.015+0530] {standard_task_runner.py:104} ERROR - Failed to execute job 419 for task send_email ((534, b'5.7.9 Application-specific password required. Learn more at\n5.7.9  https://support.google.com/mail/?p=InvalidSecondFactor 17-20020aa79211000000b0063f1a1e3003sm412547pfo.166 - gsmtp'); 83071)
[2023-07-20T12:53:38.050+0530] {local_task_job_runner.py:225} INFO - Task exited with return code 1
[2023-07-20T12:53:38.060+0530] {taskinstance.py:2653} INFO - 0 downstream tasks scheduled from follow-on schedule check
