[2023-06-29T12:10:32.083+0530] {taskinstance.py:1103} INFO - Dependencies all met for dep_context=non-requeueable deps ti=<TaskInstance: Dag_v2.second_task scheduled__2023-06-28T00:00:00+00:00 [queued]>
[2023-06-29T12:10:32.090+0530] {taskinstance.py:1103} INFO - Dependencies all met for dep_context=requeueable deps ti=<TaskInstance: Dag_v2.second_task scheduled__2023-06-28T00:00:00+00:00 [queued]>
[2023-06-29T12:10:32.091+0530] {taskinstance.py:1308} INFO - Starting attempt 3 of 8
[2023-06-29T12:10:32.117+0530] {taskinstance.py:1327} INFO - Executing <Task(BashOperator): second_task> on 2023-06-28 00:00:00+00:00
[2023-06-29T12:10:32.121+0530] {standard_task_runner.py:57} INFO - Started process 73967 to run task
[2023-06-29T12:10:32.125+0530] {standard_task_runner.py:84} INFO - Running: ['airflow', 'tasks', 'run', 'Dag_v2', 'second_task', 'scheduled__2023-06-28T00:00:00+00:00', '--job-id', '72', '--raw', '--subdir', 'DAGS_FOLDER/dag_with_bash_operator.py', '--cfg-path', '/tmp/tmpegmr2j66']
[2023-06-29T12:10:32.126+0530] {standard_task_runner.py:85} INFO - Job 72: Subtask second_task
[2023-06-29T12:10:32.174+0530] {task_command.py:410} INFO - Running <TaskInstance: Dag_v2.second_task scheduled__2023-06-28T00:00:00+00:00 [running]> on host neosoft-Latitude-E5270
[2023-06-29T12:10:32.240+0530] {taskinstance.py:1545} INFO - Exporting env vars: AIRFLOW_CTX_DAG_OWNER='airflow' AIRFLOW_CTX_DAG_ID='Dag_v2' AIRFLOW_CTX_TASK_ID='second_task' AIRFLOW_CTX_EXECUTION_DATE='2023-06-28T00:00:00+00:00' AIRFLOW_CTX_TRY_NUMBER='3' AIRFLOW_CTX_DAG_RUN_ID='scheduled__2023-06-28T00:00:00+00:00'
[2023-06-29T12:10:32.242+0530] {subprocess.py:63} INFO - Tmp dir root location: /tmp
[2023-06-29T12:10:32.242+0530] {subprocess.py:75} INFO - Running command: ['/usr/bin/bash', '-c', 'echo,i am task2 & will be running after task1!']
[2023-06-29T12:10:32.249+0530] {subprocess.py:86} INFO - Output:
[2023-06-29T12:10:32.250+0530] {subprocess.py:93} INFO - /usr/bin/bash: echo,i: command not found
[2023-06-29T12:10:32.250+0530] {subprocess.py:93} INFO - /usr/bin/bash: will: command not found
[2023-06-29T12:10:32.251+0530] {subprocess.py:97} INFO - Command exited with return code 127
[2023-06-29T12:10:32.260+0530] {taskinstance.py:1824} ERROR - Task failed with exception
Traceback (most recent call last):
  File "/home/neosoft/airflow/py_env/lib/python3.8/site-packages/airflow/operators/bash.py", line 210, in execute
    raise AirflowException(
airflow.exceptions.AirflowException: Bash command failed. The command returned a non-zero exit code 127.
[2023-06-29T12:10:32.262+0530] {taskinstance.py:1345} INFO - Marking task as UP_FOR_RETRY. dag_id=Dag_v2, task_id=second_task, execution_date=20230628T000000, start_date=20230629T064032, end_date=20230629T064032
[2023-06-29T12:10:32.287+0530] {standard_task_runner.py:104} ERROR - Failed to execute job 72 for task second_task (Bash command failed. The command returned a non-zero exit code 127.; 73967)
[2023-06-29T12:10:32.296+0530] {local_task_job_runner.py:225} INFO - Task exited with return code 1
[2023-06-29T12:10:32.319+0530] {taskinstance.py:2653} INFO - 0 downstream tasks scheduled from follow-on schedule check
